<?xml version="1.0"?>
<robot name="visual">

  <material name="blue">
    <color rgba="0 0 0.8 1"/>
  </material>
  <material name="black">
    <color rgba="0 0 0 1"/>
  </material>
  <material name="white">
    <color rgba="1 1 1 1"/>
  </material>

  <link name="base_link">
    <inertial>
      <origin xyz="0 0 0" />
      <mass value="1.0" />
      <inertia  ixx="1.0" ixy="0.0"  ixz="0.0"  iyy="100.0"  iyz="0.0"  izz="1.0" />
    </inertial>
    <visual>
      <origin xyz="0 0 0.25" rpy="0 0 0" />
      <geometry>
        <cylinder length="0.5" radius="0.2"/>
      </geometry>
      <material name="white"/>
    </visual>
    <collision>
      <origin xyz="0 0 0.25" rpy="0 0 0" />
      <geometry>
        <cylinder length="0.5" radius="0.2"/>
      </geometry>
      <material name="white"/>
    </collision>
  </link>

  <link name="link1">
    <inertial>
      <origin xyz="0 0 0" />
      <mass value="1.0" />
      <inertia  ixx="1.0" ixy="0.0"  ixz="0.0"  iyy="100.0"  iyz="0.0"  izz="1.0" />
    </inertial>
    <visual>
      <origin xyz="0 0 0.1" rpy="0 0 0" />
      <geometry>
        <sphere radius="0.1"/>
      </geometry>
      <material name="white"/>
    </visual>
    <collision>
      <origin xyz="0 0 0.1" rpy="0 0 0" />
      <geometry>
        <sphere radius="0.1"/>
      </geometry>
      <material name="white"/>
    </collision>
  </link>  

  <joint name="joint1" type="revolute">
    <parent link="base_link"/>
    <child link="link1"/>
    <origin xyz="0 0 0.5"/>
    <axis xyz="0 0 1"/>
    <limit effort="30" velocity="1.0" lower="-1.57" upper="1.57" />
  </joint>

  <link name="link2">
    <inertial>
      <origin xyz="0 0 0" />
      <mass value="1.0" />
      <inertia  ixx="1.0" ixy="0.0"  ixz="0.0"  iyy="100.0"  iyz="0.0"  izz="1.0" />
    </inertial>
    <visual>
      <origin xyz="0 0 0.3" rpy="0 0 0" />
      <geometry>
        <cylinder length="0.4" radius="0.05"/>
        <!-- <box size="0.05 0.1 0.4"/> -->
      </geometry>
      <material name="white"/>
    </visual>
    <collision>
      <origin xyz="0 0 0.3" rpy="0 0 0" />
      <geometry>
        <cylinder length="0.4" radius="0.05"/>
        <!-- <box size="0.05 0.1 0.4"/> -->
      </geometry>
      <material name="white"/>
    </collision>
  </link>

  <joint name="joint2" type="revolute">
    <parent link="link1"/>
    <child link="link2"/>
    <origin xyz="0 0 0.1"/>
    <axis xyz="0 1 0"/>
    <limit effort="30" velocity="1.0" lower="-1.57" upper="1.57" />
  </joint>
  
  <link name="link3">
    <inertial>
      <origin xyz="0 0 0" />
      <mass value="1.0" />
      <inertia  ixx="1.0" ixy="0.0"  ixz="0.0"  iyy="100.0"  iyz="0.0"  izz="1.0" />
    </inertial>
    <visual>
      <origin xyz="0 0 0.1" rpy="0 0 0" />
      <geometry>
        <sphere radius="0.1"/>
      </geometry>
      <material name="white"/>
    </visual>
    <collision>
      <origin xyz="0 0 0.1" rpy="0 0 0" />
      <geometry>
        <sphere radius="0.1"/>
      </geometry>
      <material name="white"/>
    </collision>
  </link>  

  <joint name="joint3" type="revolute">
    <parent link="link2"/>
    <child link="link3"/>
    <origin xyz="0 0 0.5"/>
    <axis xyz="0 0 1"/>
    <limit effort="30" velocity="1.0" lower="-1.57" upper="1.57" />
  </joint>

  <link name="link4">
    <inertial>
      <origin xyz="0 0 0" />
      <mass value="1.0" />
      <inertia  ixx="1.0" ixy="0.0"  ixz="0.0"  iyy="100.0"  iyz="0.0"  izz="1.0" />
    </inertial>
    <visual>
      <origin xyz="0 0 0.2" rpy="0 0 0" />
      <geometry>
        <cylinder length="0.2" radius="0.05"/>
        <!-- <box size="0.05 0.1 0.4"/> -->
      </geometry>
      <material name="white"/>
    </visual>
    <collision>
      <origin xyz="0 0 0.2" rpy="0 0 0" />
      <geometry>
        <cylinder length="0.2" radius="0.05"/>
        <!-- <box size="0.05 0.1 0.4"/> -->
      </geometry>
      <material name="white"/>
    </collision>
  </link>

  <joint name="joint4" type="revolute">
    <parent link="link3"/>
    <child link="link4"/>
    <origin xyz="0 0 0.1"/>
    <axis xyz="1 0 0"/>
    <limit effort="30" velocity="1.0" lower="-1.57" upper="1.57" />
  </joint>
  
</robot>
